Workbook
Name \\aa: #REF!
Name \\zzzz: #REF!
Name \0: #REF!
Name \1: #N/A
Name \3: #REF!
Name \4: #REF!
Name \A: #REF!
Name \a1: #REF!
Name \aa: #REF!
Name \B: #REF!
Name \C: #REF!
Name \c1: #REF!
Name \d: #REF!
Name \E: #REF!
Name \F: #REF!
Name \g: #REF!
Name \H: #REF!
Name \i: #REF!
Name \l: #REF!
Name \M: #REF!
Name \N: #REF!
Name \P: #REF!
Name \Q: #REF!
Name \R: #REF!
Name \s: #N/A
Name \U: #REF!
Name \V: #REF!
Name \x: #REF!
Name \z: #REF!
Name _: "tcap"
Name ______________________________________________________________Xl1: #REF!
Name _____________________________________________________________Xl1: #REF!
Name ____________________________________________________________Xl1: #REF!
Name __________________________________________________________Xl1: #REF!
Name _________________________________________________________Xl1: #REF!
Name ________________________________________________________Xl1: #REF!
Name _______________________________________________________Xl1: #REF!
Name ____________________________________________________Xl1: #REF!
Name __________________________________________________Xl1: #REF!
Name _________________________________________________Xl1: #REF!
Name ________________________________________________Xl1: #REF!
Name _______________________________________________Xl1: #REF!
Name ______________________________________________Xl1: #REF!
Name _____________________________________________Xl1: #REF!
Name ____________________________________________Xl1: #REF!
Name ___________________________________________Xl1: #REF!
Name __________________________________________b111121: #REF!
Name __________________________________________Xl1: #REF!
Name _________________________________________b111121: #REF!
Name _________________________________________Xl1: #REF!
Name ________________________________________b111121: #REF!
Name ________________________________________Xl1: #REF!
Name _______________________________________Xl1: #REF!
Name ______________________________________aba2: #REF!
Name ______________________________________b111121: #REF!
Name ______________________________________bom1: #REF!
Name ______________________________________CFB1: #REF!
Name ______________________________________CFB2: #REF!
Name ______________________________________CFB3: #REF!
Name ______________________________________DAT1: #REF!

Sheet Inputs for CF
B2: AC Capacity | C2: =650/2 -> 325 | D2: MW
B3: Inverter Capacity | C3: =C2*1.2 -> 390 | D3: MW
B4: DC Capacity | C4: =C2*1.5 -> 487.5 | D4: MWp
B5: Items | C5: Total Cost | D5: Total Cost in Crores | E5: % of Cost | F5: IDC & Risk Loading | G5: Spares & Freight Loading | H5: Total cost with IDC Loading | I5: Total Sales | J5: % of Sales/invoice | K5: Total Invoice | M5: Client Payment Terms | N5: % of CV | O5: Invoice Value | P5: Supply | Q5: Erection | R5: Civil | S5: Check
B6: Cell | C6: =D6/$C$4 -> 0.20512821 | D6: 100 | E6: =D6/$D$22 -> 0.1 | F6: =(D6/($D$22-($D$21+$D$20)))*$D$21 -> 7.5268817 | H6: =G6+F6+D6 -> 107.52688 | I6: =H6/(1-$C$23) -> 119.47431 | J6: =I6/$I$22 -> 0.10752688 | M6: Advance Payment | N6: 0.15 | O6: =(N6*$C$24)/10^7 -> 3.4188034e-08 | P6: =SUM($I$8:$I$16)*N6 -> 116.48746 | S6: =SUM(P6:R6)-O6 -> 116.48746
B7: BCD | C7: =D7/$C$4 -> 0.12307692 | D7: 60 | E7: =D7/$D$22 -> 0.06 | F7: =(D7/($D$22-($D$21+$D$20)))*$D$21 -> 4.516129 | H7: =G7+F7+D7 -> 64.516129 | I7: =H7/(1-$C$23) -> 71.684588 | J7: =I7/$I$22 -> 0.064516129
B8: Cell Tolling - Module | C8: =D8/$C$4 -> 0.82051282 | D8: 400 | E8: =D8/$D$22 -> 0.4 | F8: =(D8/($D$22-($D$21+$D$20)))*$D$21 -> 30.107527 | H8: =G8+F8+D8 -> 430.10753 | I8: =H8/(1-$C$23) -> 477.89725 | J8: =I8/$I$22 -> 0.43010753 | K8: =SUM(I6:I8) -> 669.05615 | M8: Studies, PO Placement | O8: =(N8*$C$24)/10^7 -> 0 | P8: =SUM($I$8:$I$16)*N8 -> 0 | Q8: =$I$17*$N8 -> 0 | R8: =$I$18*$N8 -> 0 | S8: =SUM(P8:R8)-O8 -> 0
B9: Inverter | C9: =D9/$C$4 -> 0.082051282 | D9: 40 | E9: =D9/$D$22 -> 0.04 | F9: =(D9/($D$22-($D$21+$D$20)))*$D$21 -> 3.0107527 | G9: =(D9/(SUM($D$9:$D$13,$D$15,$D$19))*$D$20) -> 0 | H9: =G9+F9+D9 -> 43.010753 | I9: =H9/(1-$C$23) -> 47.789725 | J9: =I9/$I$22 -> 0.043010753 | K9: =I9 -> 47.789725 | M9: Despatch | N9: 1 | O9: =(N9*$C$24)/10^7 -> 2.2792023e-07 | P9: =SUM($I$8:$I$16)*N9 -> 776.58303 | S9: =SUM(P9:R9)-O9 -> 776.58303
B10: MMS - Tracker | C10: =D10/$C$4 -> 0.12307692 | D10: 60 | E10: =D10/$D$22 -> 0.06 | F10: =(D10/($D$22-($D$21+$D$20)))*$D$21 -> 4.516129 | G10: =(D10/(SUM($D$9:$D$13,$D$15,$D$19))*$D$20) -> 0 | H10: =G10+F10+D10 -> 64.516129 | I10: =H10/(1-$C$23) -> 71.684588 | J10: =I10/$I$22 -> 0.064516129 | K10: =I10 -> 71.684588 | M10: Civil Works | N10: =Cashflow!AX30 -> 0.15 | O10: =(N10*$C$24)/10^7 -> 3.4188034e-08 | R10: =O15*N10 -> 4.4444444e-08 | S10: =SUM(P10:R10)-O10 -> 1.025641e-08
B11: Power Transformer | C11: =D11/$C$4 -> 0 | D11: 0 | E11: =D11/$D$22 -> 0 | F11: =(D11/($D$22-($D$21+$D$20)))*$D$21 -> 0 | G11: =(D11/(SUM($D$9:$D$13,$D$15,$D$19))*$D$20) -> 0 | H11: =G11+F11+D11 -> 0 | I11: =H11/(1-$C$23) -> 0 | J11: =I11/$I$22 -> 0 | K11: =I11 -> 0
B12: Cables | C12: =D12/$C$4 -> 0.082051282 | D12: 40 | E12: =D12/$D$22 -> 0.04 | F12: =(D12/($D$22-($D$21+$D$20)))*$D$21 -> 3.0107527 | G12: =(D12/(SUM($D$9:$D$13,$D$15,$D$19))*$D$20) -> 0 | H12: =G12+F12+D12 -> 43.010753 | I12: =H12/(1-$C$23) -> 47.789725 | J12: =I12/$I$22 -> 0.043010753 | K12: =I12 -> 47.789725 | M12: Installation | O12: =(N12*$C$24)/10^7 -> 0 | Q12: =O15*N12 -> 0 | S12: =SUM(P12:R12)-O12 -> 0
B13: IDT | C13: =D13/$C$4 -> 0.061538462 | D13: 30 | E13: =D13/$D$22 -> 0.03 | F13: =(D13/($D$22-($D$21+$D$20)))*$D$21 -> 2.2580645 | G13: =(D13/(SUM($D$9:$D$13,$D$15,$D$19))*$D$20) -> 0 | H13: =G13+F13+D13 -> 32.258065 | I13: =H13/(1-$C$23) -> 35.842294 | J13: =I13/$I$22 -> 0.032258065 | K13: =I13 -> 35.842294 | M13: Commissioning (BOS contractor can commission multiple blocks simultaneously) | O13: =(N13*$C$24)/10^7 -> 0 | P13: =SUM($I$8:$I$16)*N13 -> 0 | Q13: =$I$17*$N13 -> 0 | R13: =$I$18*$N13 -> 0 | S13: =SUM(P13:R13)-O13 -> 0
C14: =D14/$C$4 -> 0 | D14: 0 | E14: =D14/$D$22 -> 0 | F14: =(D14/($D$22-($D$21+$D$20)))*$D$21 -> 0 | H14: =G14+F14+D14 -> 0 | I14: =H14/(1-$C$23) -> 0 | J14: =I14/$I$22 -> 0 | K14: =I14 -> 0 | M14: Completion of PR test, all punch points, As built documentation and Handover of the complete project & submission of PBG for defect liability period | O14: =(N14*$C$24)/10^7 -> 0 | P14: =SUM($I$8:$I$16)*N14 -> 0 | Q14: =$I$17*$N14 -> 0 | R14: =$I$18*$N14 -> 0 | S14: =SUM(P14:R14)-O14 -> 0
B15: Other Supply | C15: =D15/$C$4 -> 0.16410256 | D15: 80 | E15: =D15/$D$22 -> 0.08 | F15: =(D15/($D$22-($D$21+$D$20)))*$D$21 -> 6.0215054 | G15: =(D15/(SUM($D$9:$D$13,$D$15,$D$19))*$D$20) -> 0 | H15: =G15+F15+D15 -> 86.021505 | I15: =H15/(1-$C$23) -> 95.57945 | J15: =I15/$I$22 -> 0.086021505 | K15: =I15 -> 95.57945 | M15: Total | N15: =SUM(N6:N14) -> 1.3 | O15: =SUM(O6:O14) -> 2.962963e-07 | P15: =SUM(P6:P14) -> 893.07049 | Q15: =SUM(Q6:Q14) -> 0 | R15: =SUM(R6:R14) -> 4.4444444e-08 | S15: =SUM(P15:R15)-O15 -> 893.07049
C16: =D16/$C$4 -> 0 | D16: 0 | E16: =D16/$D$22 -> 0 | F16: =(D16/($D$22-($D$21+$D$20)))*$D$21 -> 0 | H16: =G16+F16+D16 -> 0 | I16: =H16/(1-$C$23) -> 0 | J16: =I16/$I$22 -> 0 | K16: =I16 -> 0 | P16: =P15/$O$15 -> 3.0141129e+09 | Q16: =Q15/$O$15 -> 0 | R16: =R15/$O$15 -> 0.15
B17: Erection | C17: =D17/$C$4 -> 0.020512821 | D17: 10 | E17: =D17/$D$22 -> 0.01 | F17: =(D17/($D$22-($D$21+$D$20)))*$D$21 -> 0.75268817 | H17: =G17+F17+D17 -> 10.752688 | I17: =H17/(1-$C$23) -> 11.947431 | J17: =I17/$I$22 -> 0.010752688 | K17: =I17 -> 11.947431
B18: Civil | C18: =D18/$C$4 -> 0.22564103 | D18: 110 | E18: =D18/$D$22 -> 0.11 | F18: =(D18/($D$22-($D$21+$D$20)))*$D$21 -> 8.2795699 | H18: =G18+F18+D18 -> 118.27957 | I18: =H18/(1-$C$23) -> 131.42174 | J18: =I18/$I$22 -> 0.11827957 | K18: =I18 -> 131.42174
B19: Power Evacuation | C19: =D19/$C$4 -> 0 | D19: 0 | E19: =D19/$D$22 -> 0 | F19: =(D19/($D$22-($D$21+$D$20)))*$D$21 -> 0 | G19: =(D19/(SUM($D$9:$D$13,$D$15,$D$19))*$D$20) -> 0 | H19: =G19+F19+D19 -> 0 | I19: =H19/(1-$C$23) -> 0 | J19: =I19/$I$22 -> 0 | K19: =I19 -> 0
B20: Mandatory Spares & Freight | C20: =D20/$C$4 -> 0 | D20: 0 | E20: =D20/$D$22 -> 0
B21: IDC and R&C | C21: =D21/$C$4 -> 0.14358974 | D21: 70 | E21: =D21/$D$22 -> 0.07
B22: Total | C22: =SUM(C6:C21) -> 2.0512821 | D22: =SUM(D6:D21) -> 1000 | E22: =SUM(E6:E21) -> 1 | F22: =SUM(F6:F21) -> 70 | G22: =SUM(G6:G21) -> 0 | H22: =SUM(H6:H21) -> 1000 | I22: =SUM(I6:I21) -> 1111.1111 | J22: =SUM(J6:J21) -> 1 | K22: =SUM(K6:K21) -> 1111.1111
B23: GM% | C23: 0.1 | D23: 0.1
B24: Sales | C24: =C22/(1-C23) -> 2.2792023 | D24: =D22/(1-D23) -> 1111.1111
B25: Gross Margin | C25: =C24-C22 -> 0.22792023 | D25: =D24-D22 -> 111.11111

Sheet Cashflow
T2: Comm | U2: Compl | X2: PG Test
B3: Outflow | C3: Month | D3: 1 | E3: 2 | F3: 3 | G3: 4 | H3: 5 | I3: 6 | J3: 7 | K3: 8 | L3: 9 | M3: 10 | N3: 11 | O3: 12 | P3: 13 | Q3: 14 | R3: 15 | S3: 16 | T3: 17 | U3: 18 | V3: 19 | W3: =V3+1 -> 20 | X3: =W3+1 -> 21 | Y3: 22 | Z3: 23 | AA3: =Z3+1 -> 24 | AB3: =AA3+1 -> 25 | AC3: 26 | AD3: 19 | AE3: 20 | AF3: 21 | AG3: 22 | AH3: 23 | AI3: 24 | AJ3: 25 | AK3: 26 | AL3: 27 | AM3: 28 | AN3: 29 | AO3: 30 | AP3: 31 | AQ3: 32 | AR3: 33
B4: Items | C4: Value | D4: 45536 | E4: 45566 | F4: 45597 | G4: 45627 | H4: 45658 | I4: 45689 | J4: 45717 | K4: 45748 | L4: 45778 | M4: 45809 | N4: 45839 | O4: 45870 | P4: 45901 | Q4: 45931 | R4: 45962 | S4: 45992 | T4: 46023 | U4: 46054 | V4: 46082 | W4: 46113 | X4: 46143 | Y4: 46174 | Z4: 46204 | AA4: 46235 | AB4: 46266 | AC4: 46296 | AD4: 46327 | AE4: 46357 | AF4: 46388 | AG4: 46419 | AH4: 46447 | AI4: 46478 | AJ4: 46508 | AK4: 46539 | AL4: 46569 | AM4: 46600 | AN4: 46631 | AO4: 46661 | AP4: 46692 | AQ4: 46722 | AR4: 46753 | AT4: Total | AU4: Check | AW4: Payment Terms/Assumptions | AX4: Delivery No of Months/Lots
B5: ='Inputs for CF'!B6 -> Cell | C5: ='Inputs for CF'!$D6 -> 100 | L5: =$C5/$AX5 -> 33.333333 | N5: =$C5/$AX5 -> 33.333333 | P5: =$C5/$AX5 -> 33.333333 | AT5: =SUM(D5:AR5) -> 100 | AU5: =AT5-C5 -> 0 | AW5: 100% Credit period - 90 days | AX5: 3
B6: ='Inputs for CF'!B7 -> BCD | C6: ='Inputs for CF'!$D7 -> 60 | I6: =$C6/$AX6 -> 20 | K6: =$C6/$AX6 -> 20 | M6: =$C6/$AX6 -> 20 | AT6: =SUM(D6:AR6) -> 60 | AU6: =AT6-C6 -> 0 | AW6: Immediate after receipt at port | AX6: 3
B7: ='Inputs for CF'!B8 -> Cell Tolling - Module | C7: ='Inputs for CF'!D8 -> 400 | Q7: =$C$7/$AX$7*0.8 -> 45.714286 | R7: =$C$7/$AX$7 -> 57.142857 | S7: =$C$7/$AX$7 -> 57.142857 | T7: =$C$7/$AX$7 -> 57.142857 | U7: =$C$7/$AX$7 -> 57.142857 | V7: =$C$7/$AX$7 -> 57.142857 | W7: =$C$7/$AX$7 -> 57.142857 | X7: =$C$7/$AX$7*0.15 -> 8.5714286 | Y7: =$C$7/$AX$7*0.05 -> 2.8571429 | AT7: =SUM(D7:AR7) -> 400 | AU7: =AT7-C7 -> 0 | AW7: 100% Credit period - 180 days VFS | AX7: 7
B8: ='Inputs for CF'!B9 -> Inverter | C8: ='Inputs for CF'!D9 -> 40 | M8: =($C$8)/$AX$8 -> 8 | N8: =($C$8)/$AX$8 -> 8 | O8: =($C$8)/$AX$8 -> 8 | P8: =($C$8)/$AX$8 -> 8 | Q8: =($C$8)/$AX$8 -> 8 | AT8: =SUM(D8:AR8) -> 40 | AU8: =AT8-C8 -> 0 | AW8: 10% advance, 90% Credit period - 90 days | AX8: 5
B9: ='Inputs for CF'!B10 -> MMS - Tracker | C9: ='Inputs for CF'!D10 -> 60 | J9: =($C$9)/$AX$9 -> 10 | K9: =($C$9)/$AX$9 -> 10 | L9: =($C$9)/$AX$9 -> 10 | M9: =($C$9)/$AX$9 -> 10 | N9: =($C$9)/$AX$9 -> 10 | O9: =($C$9)/$AX$9 -> 10 | AT9: =SUM(D9:AR9) -> 60 | AU9: =AT9-C9 -> 0 | AW9: 100% Credit period - 60 days | AX9: 6
B10: ='Inputs for CF'!B11 -> Power Transformer | C10: ='Inputs for CF'!D11 -> 0 | AT10: =SUM(D10:AR10) -> 0 | AU10: =AT10-C10 -> 0 | AW10: 100% Credit period - 90 days | AX10: 2
B11: ='Inputs for CF'!B12 -> Cables | C11: ='Inputs for CF'!D12 -> 40 | L11: =$C11/$AX11 -> 5.7142857 | M11: =$C11/$AX11 -> 5.7142857 | N11: =$C11/$AX11 -> 5.7142857 | O11: =$C11/$AX11 -> 5.7142857 | P11: =$C11/$AX11 -> 5.7142857 | Q11: =$C11/$AX11 -> 5.7142857 | R11: =$C11/$AX11 -> 5.7142857 | AT11: =SUM(D11:AR11) -> 40 | AU11: =AT11-C11 -> 0 | AW11: 100% Credit period - 90 days | AX11: 7
B12: ='Inputs for CF'!B13 -> IDT | C12: ='Inputs for CF'!D13 -> 30 | M12: =$C12/$AX12 -> 6 | N12: =$C12/$AX12 -> 6 | O12: =$C12/$AX12 -> 6 | P12: =$C12/$AX12 -> 6 | Q12: =$C12/$AX12 -> 6 | AT12: =SUM(D12:AR12) -> 30 | AU12: =AT12-C12 -> 0 | AW12: 100% Credit period - 90 days | AX12: 5
B13: ='Inputs for CF'!B14 -> 0 | C13: ='Inputs for CF'!D14 -> 0 | AT13: =SUM(D13:AR13) -> 0 | AU13: =AT13-C13 -> 0 | AW13: 100% Credit period - 60 days | AX13: 3
B14: ='Inputs for CF'!B15 -> Other Supply | C14: ='Inputs for CF'!D15 -> 80 | I14: =$C14/$AX14 -> 10 | J14: =$C14/$AX14 -> 10 | K14: =$C14/$AX14 -> 10 | L14: =$C14/$AX14 -> 10 | M14: =$C14/$AX14 -> 10 | N14: =$C14/$AX14 -> 10 | O14: =$C14/$AX14 -> 10 | P14: =$C14/$AX14 -> 10 | AT14: =SUM(D14:AR14) -> 80 | AU14: =AT14-C14 -> 0 | AW14: 100% Credit period - 45 days | AX14: 8
B15: ='Inputs for CF'!B16 -> 0 | C15: ='Inputs for CF'!D16 -> 0 | M15: =$C15/$AX15 -> 0 | N15: =$C15/$AX15 -> 0 | O15: =$C15/$AX15 -> 0 | P15: =$C15/$AX15 -> 0 | Q15: =$C15/$AX15 -> 0 | R15: =$C15/$AX15 -> 0 | S15: =$C15/$AX15 -> 0 | T15: =$C15/$AX15 -> 0 | AC15: =$C15/$AX15 -> 0 | AD15: =$C15/$AX15 -> 0 | AE15: =$C15/$AX15 -> 0 | AF15: =$C15/$AX15 -> 0 | AG15: =$C15/$AX15 -> 0 | AH15: =$C15/$AX15 -> 0 | AI15: =$C15/$AX15 -> 0 | AJ15: =$C15/$AX15 -> 0 | AK15: =$C15/$AX15 -> 0 | AT15: =SUM(D15:AR15) -> 0 | AU15: =AT15-C15 -> 0 | AW15: 100% Credit period - 60 days | AX15: 17
B16: ='Inputs for CF'!B17 -> Erection | C16: ='Inputs for CF'!D17 -> 10 | J16: =$C$16*5% -> 0.5 | K16: =$C$16*5% -> 0.5 | L16: =$C$16*9% -> 0.9 | M16: =$C$16*14% -> 1.4 | N16: =$C$16*14% -> 1.4 | O16: =$C$16*14% -> 1.4 | P16: =$C$16*9% -> 0.9 | Q16: =$C$16*10% -> 1 | R16: =$C$16*8% -> 0.8 | S16: =$C$16*5% -> 0.5 | T16: =$C$16*5% -> 0.5 | U16: =$C$16*2% -> 0.2 | AT16: =SUM(D16:AR16) -> 10 | AU16: =AT16-C16 -> 0 | AW16: 100% Credit period - 45 days | AX16: 11
B17: ='Inputs for CF'!B18 -> Civil | C17: ='Inputs for CF'!D18 -> 110 | H17: =$C$17*2% -> 2.2 | I17: =$C$17*6% -> 6.6 | J17: =$C$17*8% -> 8.8 | K17: =$C$17*12% -> 13.2 | L17: =$C$17*13% -> 14.3 | M17: =$C$17*13% -> 14.3 | N17: =$C$17*13% -> 14.3 | O17: =$C$17*9% -> 9.9 | P17: =$C$17*9% -> 9.9 | Q17: =$C$17*5% -> 5.5 | R17: =$C$17*5% -> 5.5 | S17: =$C$17*2% -> 2.2 | T17: =$C$17*2% -> 2.2 | U17: =$C$17*1% -> 1.1 | AT17: =SUM(D17:AR17) -> 110 | AU17: =AT17-C17 -> 0 | AW17: 100% Credit period - 45 days | AX17: 13
B18: ='Inputs for CF'!B19 -> Power Evacuation | C18: ='Inputs for CF'!D19 -> 0 | M18: =$C$18*10% -> 0 | N18: =$C$18*10% -> 0 | O18: =($C$18*10%) -> 0 | P18: =($C$18*10%) -> 0 | Q18: =($C$18*20%) -> 0 | R18: =($C$18*20%) -> 0 | S18: =($C$18*15%) -> 0 | T18: =($C$18*5%) -> 0 | AT18: =SUM(D18:AR18) -> 0 | AU18: =AT18-C18 -> 0 | AW18: 100% Credit period - 45 days | AX18: 7
B19: ='Inputs for CF'!B20 -> Mandatory Spares & Freight | C19: ='Inputs for CF'!D20 -> 0 | M19: =$C$19/$AX$19 -> 0 | N19: =$C$19/$AX$19 -> 0 | O19: =$C$19/$AX$19 -> 0 | AT19: =SUM(D19:AR19) -> 0 | AU19: =AT19-C19 -> 0 | AW19: 100% Credit period - 60 days | AX19: 3
B20: ='Inputs for CF'!B21 -> IDC and R&C | C20: ='Inputs for CF'!D21 -> 70 | D20: =$C$20*1% -> 0.7 | E20: =$C$20*1% -> 0.7 | F20: =$C$20*1% -> 0.7 | G20: =$C$20*2% -> 1.4 | H20: =$C$20*3% -> 2.1 | I20: =$C$20*5% -> 3.5 | J20: =$C$20*7% -> 4.9 | K20: =$C$20*7% -> 4.9 | L20: =$C$20*7% -> 4.9 | M20: =$C$20*7.5% -> 5.25 | N20: =$C$20*7.5% -> 5.25 | O20: =$C$20*9% -> 6.3 | P20: =$C$20*9% -> 6.3 | Q20: =$C$20*9% -> 6.3 | R20: =$C$20*8.5% -> 5.95 | S20: =$C$20*7% -> 4.9 | T20: =$C$20*2% -> 1.4 | U20: =$C$20*2% -> 1.4 | V20: =$C$20*2.5% -> 1.75 | W20: =$C$20*2% -> 1.4 | AT20: =SUM(D20:AR20) -> 70 | AU20: =AT20-C20 -> 0
B21: Total - Outflow | C21: =SUM(C5:C20) -> 1000 | D21: =SUM(D5:D20) -> 0.7 | E21: =SUM(E5:E20) -> 0.7 | F21: =SUM(F5:F20) -> 0.7 | G21: =SUM(G5:G20) -> 1.4 | H21: =SUM(H5:H20) -> 4.3 | I21: =SUM(I5:I20) -> 40.1 | J21: =SUM(J5:J20) -> 34.2 | ... AR21: =SUM(AR5:AR20) -> 0 | AT21: =SUM(AT5:AT20) -> 1000 | AU21: =SUM(AU5:AU20) -> 0
D22: =D48/$C$21 -> 0.0007 | E22: =E48/$C$21 -> 0.0014 | F22: =F48/$C$21 -> 0.0021 | G22: =G48/$C$21 -> 0.0035 | H22: =H48/$C$21 -> 0.0078 | I22: =I48/$C$21 -> 0.0479 | J22: =J48/$C$21 -> 0.0821 | K22: =K48/$C$21 -> 0.1407 | ... AB22: =AB48/$C$21 -> 1 | AD22: =AD48/$C$21 -> 1 | AE22: =AE48/$C$21 -> 1 | AF22: =AF48/$C$21 -> 1 | AG22: =AG48/$C$21 -> 1 | AH22: =AH48/$C$21 -> 1 | AI22: =AI48/$C$21 -> 1 | AJ22: =AJ48/$C$21 -> 1 | AK22: =AK48/$C$21 -> 1 | ... AR22: =AR48/$C$21 -> 1 | AT22: =AT21/C21 -> 1
B24: Inflow | C24: Month | D24: =D3 -> 1 | E24: =E3 -> 2 | F24: =F3 -> 3 | G24: =G3 -> 4 | H24: =H3 -> 5 | I24: =I3 -> 6 | J24: =J3 -> 7 | K24: =K3 -> 8 | ... AR24: =AR3 -> 33
B25: Items | C25: Value | D25: =D4 -> 45536 | E25: =E4 -> 45566 | F25: =F4 -> 45597 | G25: =G4 -> 45627 | H25: =H4 -> 45658 | I25: =I4 -> 45689 | J25: =J4 -> 45717 | K25: =K4 -> 45748 | ... AR25: =AR4 -> 46753 | AT25: Total | AU25: Check | AW25: Client Payment Terms ( Credit Period : 30 days) | AX25: % | AY25: Value
B26: ='Inputs for CF'!B6 -> Cell | C26: ='Inputs for CF'!K6 -> 0 | D26: =C26*$AX$28 -> 0 | AT26: =SUM(D26:AC26) -> 0 | AU26: =AT26-C26 -> 0 | AW26: Supply
B27: BCD | C27: ='Inputs for CF'!K7 -> 0 | D27: =C27*$AX$28 -> 0 | AT27: =SUM(D27:AC27) -> 0
B28: ='Inputs for CF'!B8 -> Cell Tolling - Module | C28: ='Inputs for CF'!K8 -> 669.05615 | D28: =C28*$AX$28 -> 100.35842 | M28: =(($C28*($AX$29+$AX$30))/$AX7)*0.8 -> 53.524492 | N28: =($C28*($AX$29+$AX$30))/$AX7 -> 66.905615 | O28: =($C28*($AX$29+$AX$30))/$AX7 -> 66.905615 | P28: =($C28*($AX$29+$AX$30))/$AX7 -> 66.905615 | Q28: =($C28*($AX$29+$AX$30))/$AX7 -> 66.905615 | R28: =($C28*($AX$29+$AX$30))/$AX7 -> 66.905615 | S28: =($C28*($AX$29+$AX$30))/$AX7 -> 66.905615 | T28: =(($C28*($AX$29+$AX$30))/$AX7)*0.15 -> 10.035842 | U28: =(($C28*($AX$29+$AX$30))/$AX7)*0.05 -> 3.3452808 | V28: =($C28*$AX$31) -> 16.726404 | W28: =($C28*$AX$32) -> 16.726404 | Z28: =($C28*$AX$33) -> 66.905615 | AP28: =(C28*$AX$33)*0 -> 0 | AT28: =SUM(D28:AC28) -> 669.05615 | AU28: =AT28-(C28*100%) -> 0 | AW28: Advance Payment | AX28: 0.15 | AY28: =SUM($C$28:$C$35,$C$39)*$AX28 -> 145.16129
B29: ='Inputs for CF'!B9 -> Inverter | C29: ='Inputs for CF'!K9 -> 47.789725 | D29: =C29*$AX$28 -> 7.1684588 | L29: =($C29*($AX$29+$AX$30))/$AX8 -> 6.6905615 | M29: =($C29*($AX$29+$AX$30))/$AX8 -> 6.6905615 | N29: =($C29*($AX$29+$AX$30))/$AX8 -> 6.6905615 | O29: =($C29*($AX$29+$AX$30))/$AX8 -> 6.6905615 | P29: =($C29*($AX$29+$AX$30))/$AX8 -> 6.6905615 | V29: =($C29*$AX$31) -> 1.1947431 | W29: =($C29*$AX$32) -> 1.1947431 | Z29: =($C29*$AX$33) -> 4.7789725 | AP29: =(C29*$AX$33)*0 -> 0 | AT29: =SUM(D29:AC29) -> 47.789725 | AU29: =AT29-(C29*100%) -> 0 | AW29: Against dispatch of Material from Manufacturer’s work | AX29: 0.55 | AY29: =SUM($C$28:$C$35,$C$39)*$AX29 -> 532.25806
B30: ='Inputs for CF'!B10 -> MMS - Tracker | C30: ='Inputs for CF'!K10 -> 71.684588 | D30: =C30*$AX$28 -> 10.752688 | J30: =($C30*($AX$29+$AX$30))/$AX9 -> 8.3632019 | K30: =($C30*($AX$29+$AX$30))/$AX9 -> 8.3632019 | L30: =($C30*($AX$29+$AX$30))/$AX9 -> 8.3632019 | M30: =($C30*($AX$29+$AX$30))/$AX9 -> 8.3632019 | N30: =($C30*($AX$29+$AX$30))/$AX9 -> 8.3632019 | O30: =($C30*($AX$29+$AX$30))/$AX9 -> 8.3632019 | V30: =($C30*$AX$31) -> 1.7921147 | W30: =($C30*$AX$32) -> 1.7921147 | Z30: =($C30*$AX$33) -> 7.1684588 | AP30: =(C30*$AX$33)*0 -> 0 | AT30: =SUM(D30:AC30) -> 71.684588 | AU30: =AT30-(C30*100%) -> 0 | AW30: Upon receipt of Supply of Material/Equipment at site & Acceptance thereof. | AX30: 0.15 | AY30: =SUM($C$28:$C$35,$C$39)*$AX30 -> 145.16129
B31: ='Inputs for CF'!B11 -> Power Transformer | C31: ='Inputs for CF'!K11 -> 0 | D31: =C31*$AX$28 -> 0 | P31: =($C31*($AX$29+$AX$30))/$AX10 -> 0 | Q31: =($C31*($AX$29+$AX$30))/$AX10 -> 0 | V31: =($C31*$AX$31) -> 0 | W31: =($C31*$AX$32) -> 0 | Z31: =($C31*$AX$33) -> 0 | AP31: =(C31*$AX$33)*0 -> 0 | AT31: =SUM(D31:AC31) -> 0 | AU31: =AT31-(C31*100%) -> 0 | AW31: Upon Commissioning | AX31: 0.025 | AY31: =SUM($C$28:$C$35,$C$39)*$AX31 -> 24.193548
B32: ='Inputs for CF'!B12 -> Cables | C32: ='Inputs for CF'!K12 -> 47.789725 | D32: =C32*$AX$28 -> 7.1684588 | K32: =($C32*($AX$29+$AX$30))/$AX11 -> 4.7789725 | L32: =($C32*($AX$29+$AX$30))/$AX11 -> 4.7789725 | M32: =($C32*($AX$29+$AX$30))/$AX11 -> 4.7789725 | N32: =($C32*($AX$29+$AX$30))/$AX11 -> 4.7789725 | O32: =($C32*($AX$29+$AX$30))/$AX11 -> 4.7789725 | P32: =($C32*($AX$29+$AX$30))/$AX11 -> 4.7789725 | Q32: =($C32*($AX$29+$AX$30))/$AX11 -> 4.7789725 | V32: =($C32*$AX$31) -> 1.1947431 | W32: =($C32*$AX$32) -> 1.1947431 | Z32: =($C32*$AX$33) -> 4.7789725 | AP32: =(C32*$AX$33)*0 -> 0 | AT32: =SUM(D32:AC32) -> 47.789725 | AU32: =AT32-(C32*100%) -> 0 | AW32: Upon Completion of Facilities | AX32: 0.025 | AY32: =SUM($C$28:$C$35,$C$39)*$AX32 -> 24.193548
B33: ='Inputs for CF'!B13 -> IDT | C33: ='Inputs for CF'!K13 -> 35.842294 | D33: =C33*$AX$28 -> 5.3763441 | L33: =($C33*($AX$29+$AX$30))/$AX12 -> 5.0179211 | M33: =($C33*($AX$29+$AX$30))/$AX12 -> 5.0179211 | N33: =($C33*($AX$29+$AX$30))/$AX12 -> 5.0179211 | O33: =($C33*($AX$29+$AX$30))/$AX12 -> 5.0179211 | P33: =($C33*($AX$29+$AX$30))/$AX12 -> 5.0179211 | V33: =($C33*$AX$31) -> 0.89605735 | W33: =($C33*$AX$32) -> 0.89605735 | Z33: =($C33*$AX$33) -> 3.5842294 | AP33: =(C33*$AX$33)*0 -> 0 | AT33: =SUM(D33:AC33) -> 35.842294 | AU33: =AT33-(C33*100%) -> 0 | AW33: Upon successful completion of PG Test | AX33: 0.1 | AY33: =SUM($C$28:$C$35,$C$39)*$AX33 -> 96.774194
B34: ='Inputs for CF'!B14 -> 0 | C34: ='Inputs for CF'!K14 -> 0 | D34: =C34*$AX$28 -> 0 | L34: =($C34*($AX$29+$AX$30))/$AX13 -> 0 | M34: =($C34*($AX$29+$AX$30))/$AX13 -> 0 | N34: =($C34*($AX$29+$AX$30))/$AX13 -> 0 | V34: =($C34*$AX$31) -> 0 | W34: =($C34*$AX$32) -> 0 | Z34: =($C34*$AX$33) -> 0 | AT34: =SUM(D34:AC34) -> 0 | AU34: =AT34-(C34*100%) -> 0 | AW34: Services
B35: ='Inputs for CF'!B15 -> Other Supply | C35: ='Inputs for CF'!K15 -> 95.57945 | D35: =C35*$AX$28 -> 14.336918 | J35: =($C35*($AX$29+$AX$30))/$AX14 -> 8.3632019 | K35: =($C35*($AX$29+$AX$30))/$AX14 -> 8.3632019 | L35: =($C35*($AX$29+$AX$30))/$AX14 -> 8.3632019 | M35: =($C35*($AX$29+$AX$30))/$AX14 -> 8.3632019 | N35: =($C35*($AX$29+$AX$30))/$AX14 -> 8.3632019 | O35: =($C35*($AX$29+$AX$30))/$AX14 -> 8.3632019 | P35: =($C35*($AX$29+$AX$30))/$AX14 -> 8.3632019 | Q35: =($C35*($AX$29+$AX$30))/$AX14 -> 8.3632019 | V35: =($C35*$AX$31) -> 2.3894863 | W35: =($C35*$AX$32) -> 2.3894863 | Z35: =($C35*$AX$33) -> 9.557945 | AP35: =(C35*$AX$33)*0 -> 0 | AT35: =SUM(D35:AC35) -> 95.57945 | AU35: =AT35-(C35*100%) -> 0 | AW35: Interest bearing advance payment | AX35: 0.1 | AY35: =SUM($C$36:$C$38)*AX35 -> 14.336918
B36: ='Inputs for CF'!B16 -> 0 | C36: ='Inputs for CF'!K16 -> 0 | D36: =C36*$AX$26 -> 0 | Q36: =(C36*$AX$32) -> 0 | AT36: =SUM(D36:AC36) -> 0 | AU36: =AT36-(C36*100%) -> 0 | AW36: On pro-rata basis against Completion and certification | AX36: 0.75 | AY36: =SUM($C$36:$C$38)*AX36 -> 107.52688
A37: 0.19 | B37: ='Inputs for CF'!B17 -> Erection | C37: ='Inputs for CF'!K17 -> 11.947431 | D37: =C37*$AX$26 -> 0 | K37: =J16*(1+$A$37)*85% -> 0.50575 | L37: =K16*(1+$A$37)*85% -> 0.50575 | M37: =L16*(1+$A$37)*85% -> 0.91035 | N37: =M16*(1+$A$37)*85% -> 1.4161 | O37: =N16*(1+$A$37)*85% -> 1.4161 | P37: =O16*(1+$A$37)*85% -> 1.4161 | Q37: =P16*(1+$A$37)*85% -> 0.91035 | R37: =Q16*(1+$A$37)*85% -> 1.0115 | ... V37: =U16*(1+$A$37)*85% -> 0.2023 | W37: =V16*(1+$A$37)*85%+($C37*2.5%) -> 0.29868578 | X37: =W16*(1+$A$37)*85%+($C37*2.5%) -> 0.29868578 | Y37: =X16*(1+$A$37)*85% -> 0 | Z37: =$C37*10% -> 1.1947431 | AT37: =SUM(D37:AC37) -> 11.907115 | AU37: =AT37-C37 -> -0.040316607 | AW37: Upon Commissioning | AX37: 0.025 | AY37: =SUM($C$36:$C$38)*AX37 -> 3.5842294
A38: =A37 -> 0.19 | B38: ='Inputs for CF'!B18 -> Civil | C38: ='Inputs for CF'!K18 -> 131.42174 | I38: =H17*(1+$A$37)*85% -> 2.2253 | J38: =I17*(1+$A$37)*85% -> 6.6759 | K38: =J17*(1+$A$37)*85% -> 8.9012 | L38: =K17*(1+$A$37)*85% -> 13.3518 | M38: =L17*(1+$A$37)*85% -> 14.46445 | N38: =M17*(1+$A$37)*85% -> 14.46445 | O38: =N17*(1+$A$37)*85% -> 14.46445 | P38: =O17*(1+$A$37)*85% -> 10.01385 | ... V38: =U17*(1+$A$37)*85% -> 1.11265 | W38: =V17*(1+$A$37)*85%+($C38*2.5%) -> 3.2855436 | X38: =W17*(1+$A$37)*85%+($C38*2.5%) -> 3.2855436 | Z38: =$C38*10% -> 13.142174 | AT38: =SUM(D38:AC38) -> 130.97826 | AU38: =AT38-C38 -> -0.44348268 | AW38: Upon Completion of Facilities | AX38: 0.025 | AY38: =SUM($C$36:$C$38)*AX38 -> 3.5842294
B39: ='Inputs for CF'!B19 -> Power Evacuation | C39: ='Inputs for CF'!K19 -> 0 | D39: =C39*$AX$28 -> 0 | N39: =($C39*($AX$29+$AX$30))/$AX18 -> 0 | O39: =($C39*($AX$29+$AX$30))/$AX18 -> 0 | P39: =($C39*($AX$29+$AX$30))/$AX18 -> 0 | Q39: =($C39*($AX$29+$AX$30))/$AX18 -> 0 | R39: =($C39*($AX$29+$AX$30))/$AX18 -> 0 | S39: =($C39*($AX$29+$AX$30))/$AX18 -> 0 | T39: =($C39*($AX$29+$AX$30))/$AX18 -> 0 | V39: =($C39*$AX$31) -> 0 | W39: =($C39*$AX$32) -> 0 | Z39: =($C39*$AX$33) -> 0 | AP39: =(C39*$AX$33)*0 -> 0 | AT39: =SUM(D39:AC39) -> 0 | AU39: =AT39-(C39*100%) -> 0 | AW39: Upon successful completion of PG Test | AX39: 0.1 | AY39: =SUM($C$36:$C$38)*AX39 -> 14.336918
B40: Key equipment erection | AT40: =SUM(D40:AC40) -> 0 | AU40: =AT40-(C40*100%) -> 0
B41: ='Inputs for CF'!B20 -> Mandatory Spares & Freight | C41: ='Inputs for CF'!K20 -> 0 | AT41: =SUM(D41:AC41) -> 0 | AU41: =AT41-(C41*100%) -> 0
B42: ='Inputs for CF'!B21 -> IDC and R&C | C42: ='Inputs for CF'!K21 -> 0 | AT42: =SUM(D42:AC42) -> 0 | AU42: =AT42-C42 -> 0
...
